<?xml version='1.0'?>

<robot name="myrobot" xmlns:xacro="http://www.ros.org/wiki/xacro">



  <xacro:include filename="$(find mybot_description)/urdf/mybot.gazebo" />
  <xacro:include filename="$(find mybot_description)/urdf/materials.xacro" />
  <xacro:include filename="$(find mybot_description)/urdf/macros.xacro" />


  <link name='chassis'>
    <pose>0 0 0.6 0 0 0</pose>

    <inertial>
      <mass value="30.0"/>
      <origin xyz="0 0 0" rpy="0 0 0"/>
      <inertia
          ixx="1.078" ixy="0" ixz="0"
          iyy="2.09" iyz="0"
          izz="2.61"
      />
    </inertial>

<!--
    <inertial>
      <mass value="35.0"/>
      <origin xyz="0 0 0" rpy="0 0 0"/>
      <inertia
          ixx="1.8" ixy="0" ixz="0"
          iyy="2.5" iyz="0"
          izz="2"
      />
    </inertial>

    <inertial>
      <mass value="65.0"/>
      <origin xyz="0 0 0" rpy="0 0 0"/>
      <inertia
          ixx="2.156916" ixy="0" ixz="0"
          iyy="4.1919" iyz="0"
          izz="5.2259"
      />
    </inertial>

-->

    <collision name='collision'>
      <geometry>
        <box size=".89 .59 .35"/>
      </geometry>
    </collision>

    <visual name='chassis_visual'>
      <origin xyz="0 0 0" rpy=" 0 0 0"/>
      <geometry>
        <box size=".89 .59 .35"/>
      </geometry>
    </visual>

<!--Right-->

    <collision name='caster_collision'>
      <origin xyz="-0.4 0.0 -0.2" rpy=" 0 0 0"/>
      <geometry>
        <sphere radius="0.08"/>
      </geometry>
      <surface>
        <friction>
          <ode>
            <mu>0</mu>
            <mu2>0</mu2>
            <slip1>1.0</slip1>
            <slip2>1.0</slip2>
          </ode>
        </friction>
      </surface>
    </collision>

    <visual name='caster_visual'>
      <origin xyz="-0.4 0.0 -0.2" rpy=" 0 0 0"/>
      <geometry>
        <sphere radius="0.08"/>
      </geometry>
    </visual>

    <collision name='caster_collision_front'>
      <origin xyz="0.4 0.0 -0.2" rpy=" 0 0 0"/>
      <geometry>
        <sphere radius="0.08"/>
      </geometry>
      <surface>
        <friction>
          <ode>
            <mu>0</mu>
            <mu2>0</mu2>
            <slip1>1.0</slip1>
            <slip2>1.0</slip2>
          </ode>
        </friction>
      </surface>
    </collision>

    <visual name='caster_visual_front'>
      <origin xyz="0.4 0.0 -0.2" rpy=" 0 0 0"/>
      <geometry>
        <sphere radius="0.08"/>
      </geometry>
    </visual>


<!--Left

    <collision name='caster_collision'>
      <origin xyz="-0.4 -0.2 -0.2" rpy=" 0 0 0"/>
      <geometry>
        <sphere radius="0.08"/>
      </geometry>
      <surface>
        <friction>
          <ode>
            <mu>0</mu>
            <mu2>0</mu2>
            <slip1>1.0</slip1>
            <slip2>1.0</slip2>
          </ode>
        </friction>
      </surface>
    </collision>

    <visual name='caster_visual'>
      <origin xyz="-0.4 -0.2 -0.2" rpy=" 0 0 0"/>
      <geometry>
        <sphere radius="0.08"/>
      </geometry>
    </visual>

    <collision name='caster_collision_front_L'>
      <origin xyz="0.4 -0.2 -0.2" rpy=" 0 0 0"/>
      <geometry>
        <sphere radius="0.08"/>
      </geometry>
      <surface>
        <friction>
          <ode>
            <mu>0</mu>
            <mu2>0</mu2>
            <slip1>1.0</slip1>
            <slip2>1.0</slip2>
          </ode>
        </friction>
      </surface>
    </collision>

    <visual name='caster_visual_front_L'>
      <origin xyz="0.4 -0.2 -0.2" rpy=" 0 0 0"/>
      <geometry>
        <sphere radius="0.08"/>
      </geometry>
    </visual>

-->

  </link>


  <link name="left_wheel">
    <!--origin xyz="0.1 0.13 0.1" rpy="0 1.5707 1.5707"/-->
    <collision name="collision">
      <origin xyz="0 0 0" rpy="0 1.5707 1.5707"/>
      <geometry>
        <cylinder radius="0.08" length="0.06"/>
      </geometry>
    </collision>
    <visual name="left_wheel_visual">
      <origin xyz="0 0 0" rpy="0 1.5707 1.5707"/>
      <geometry>
        <cylinder radius="0.08" length="0.06"/>
      </geometry>
    </visual>
    <inertial>
      <origin xyz="0 0 0" rpy="0 1.5707 1.5707"/>
      <mass value="10"/>
      <cylinder_inertia m="10" r="0.1" h="0.06"/>
      <inertia
        ixx="0.028" ixy="0.0" ixz="0.0"
        iyy="0.028" iyz="0.0"
        izz="0.05"/>
    </inertial>
  </link>

  <link name="right_wheel">
    <!--origin xyz="0.1 -0.13 0.1" rpy="0 1.5707 1.5707"/-->
    <collision name="collision">
      <origin xyz="0 0 0" rpy="0 1.5707 1.5707"/>
      <geometry>
        <cylinder radius="0.08" length="0.06"/>
      </geometry>
    </collision>
    <visual name="right_wheel_visual">
      <origin xyz="0 0 0" rpy="0 1.5707 1.5707"/>
      <geometry>
        <cylinder radius="0.08" length="0.06"/>
      </geometry>
    </visual>
    <inertial>
      <origin xyz="0 0 0" rpy="0 1.5707 1.5707"/>
      <mass value="10"/>
      <cylinder_inertia m="10" r="0.1" h="0.06"/>
      <inertia
        ixx="0.028" ixy="0.0" ixz="0.0"
        iyy="0.028" iyz="0.0"
        izz="0.05"/>
    </inertial>
  </link>


  <joint type="continuous" name="left_wheel_hinge">
    <origin xyz="0 0.25 -0.2" rpy="0 0 0"/>
    <child link="left_wheel"/>
    <parent link="chassis"/>
    <axis xyz="0 1 0" rpy="0 0 0"/>
    <limit effort="100" velocity="100"/>
    <joint_properties damping="0.0" friction="0.0"/>
  </joint>

  <joint type="continuous" name="right_wheel_hinge">
    <origin xyz="0 -0.25 -0.2" rpy="0 0 0"/>
    <child link="right_wheel"/>
    <parent link="chassis"/>
    <axis xyz="0 1 0" rpy="0 0 0"/>
    <limit effort="100" velocity="100"/>
    <joint_properties damping="0.0" friction="0.0"/>
  </joint>


</robot>
